 # except Exception as e:
        #     # increment failure count
        #     failure_count += 1
        #     # send pushbullet notification on third failure
        #     if failure_count == 3 :
        #         pb.push_note("Group Me -","Error in main function  and function tests failing", str(e))
        #         print(f"Error in main function: {e}")
        #         failure_count = 0
        #         break
        #     # wait for 5 minutes before trying again
        #     time.sleep(300)
        #     __main__()
        